<?xml version="1.0" ?>
<robot name="aid_robot"
  xmlns:xacro="http://ros.org/wiki/xacro">

  <link name="base_footprint"/>

  <joint name="base_joint" type="fixed">
    <parent link="base_footprint"/>
    <child link="base_link"/>
    <origin xyz="0.0 0.0 0.0105" rpy="0 0 0"/>
  </joint>

  <link name="base_link">
  </link>

  <joint name="wheel_left_joint" type="continuous">
    <parent link="base_link"/>
    <child link="wheel_left_link"/>
    <origin xyz="0.0 0.115 0.0" rpy="-1.57 0 0"/>
    <axis xyz="0 0 1"/>
  </joint>

  <link name="wheel_left_link"> 
  </link>

  <joint name="wheel_right_joint" type="continuous">
    <parent link="base_link"/>
    <child link="wheel_right_link"/>
    <origin xyz="0.0 -0.115 0.0" rpy="-1.57 0 0"/>
    <axis xyz="0 0 1"/>
  </joint>

  <link name="wheel_right_link">
  </link>


  <joint name="imu_joint" type="fixed">
    <parent link="base_link"/>
    <child link="imu_link"/>
    <origin xyz="-0.03 0 0.0" rpy="0 0 0"/>
  </joint>

  <link name="imu_link"> 
  </link>

  <joint name="scan_joint" type="fixed">
    <parent link="base_link"/>
    <child link="base_scan"/>
    <origin xyz="-0.04485 0 0.19" rpy="0 0 -1.573"/>
  </joint>

  <link name="base_scan"> 
  </link>

  <joint name="camera_joint" type="fixed">
    <parent link="base_link"/>
    <child link="camera_link"/>
    <origin xyz="0.13254 0 0.13085" rpy="3.141 0 0"/>
  </joint>

  <link name="camera_link"> 
  </link>

  <joint name="ultrasonic_front_joint" type="fixed">
    <parent link="base_link"/>
    <child link="ultrasonic_front_link"/>
    <origin xyz="0.146 0 0.02" rpy="0 0 0"/>
  </joint>
  <link name="ultrasonic_front_link"> 
  </link>

  <joint name="ultrasonic_front_left_joint" type="fixed">
    <parent link="base_link"/>
    <child link="ultrasonic_front_left_link"/>
    <origin xyz="0.146 0.05 0.02" rpy="0 0 0.436"/>
  </joint>
  <link name="ultrasonic_front_left_link"> 
  </link>

  <joint name="ultrasonic_front_right_joint" type="fixed">
    <parent link="base_link"/>
    <child link="ultrasonic_front_right_link"/>
    <origin xyz="0.146 -0.05 0.02" rpy="0 0 -0.436"/>
  </joint>
  <link name="ultrasonic_front_right_link"> 
  </link>

  <joint name="ultrasonic_rear_joint" type="fixed">
    <parent link="base_link"/>
    <child link="ultrasonic_rear_link"/>
    <origin xyz="-0.25274 0 -0.04" rpy="0 0 3.14"/>
  </joint>
  <link name="ultrasonic_rear_link"> 
  </link>

  <joint name="ultrasonic_rear_left_joint" type="fixed">
    <parent link="base_link"/>
    <child link="ultrasonic_rear_left_link"/>
    <origin xyz="-0.17728 0.094 -0.02586" rpy="0 0 1.885"/>
  </joint>
  <link name="ultrasonic_rear_left_link"> 
  </link>

  <joint name="ultrasonic_rear_right_joint" type="fixed">
    <parent link="base_link"/>
    <child link="ultrasonic_rear_right_link"/>
    <origin xyz="-0.17728 -0.094 -0.02586" rpy="0 0 -1.885"/>
  </joint>
  <link name="ultrasonic_rear_right_link">
  </link>

  <joint name="laser_front_left_joint" type="fixed">
    <parent link="base_link"/>
    <child link="laser_front_left_link"/>
    <origin xyz="0.13254 0.05 0.0" rpy="0 0 0"/>
  </joint>
  <link name="laser_front_left_link">
  </link>

  <joint name="laser_front_right_joint" type="fixed">
    <parent link="base_link"/>
    <child link="laser_front_right_link"/>
    <origin xyz="0.13254 -0.05 0.0" rpy="0 0 0"/>
  </joint>
  <link name="laser_front_right_link">
  </link>

</robot>
